Workbook

Sheet DB
A1: Fecha | B1: Mes | C1: Año | D1: Canal | E1: Proveedor | F1: club | G1: ISSUE | H1: Categoria | I1: DESCRIPCION | J1: Nivel | K1: Resultado
A2: 46046 | B2: =IF(LEN(A2)=0,"",TEXT(A2,"mmmm")) -> enero | C2: =IF(LEN(A2)=0,"",TEXT(A2,"aaaa")) -> 2026 | D2: Web | E2: Wasabi | F2: Wasabi - Club 2 | G2: 112 | H2: =IF(LEN(G2)=0,"",VLOOKUP(G2,Issues!A:D,2,FALSE)) -> (100) Alta | I2: =IF(LEN(G2)=0,"",VLOOKUP(G2,Issues!A:D,3,FALSE)) -> Falla en alta a traves de tienda. | J2: =IF(LEN(G2)=0,"",VLOOKUP(G2,Issues!A:D,4,FALSE)) -> Critico | K2: =IF(LEN(G2)=0,"",IF(OR(J2="critico",J2="Medio",J2="Bajo"),"Issue",IF(J2="Prueba OK","OK",""))) -> Issue
A3: 46095 | B3: =IF(LEN(A3)=0,"",TEXT(A3,"mmmm")) -> marzo | C3: =IF(LEN(A3)=0,"",TEXT(A3,"aaaa")) -> 2026 | D3: Wap | E3: Renxo | F3: Renxo - Club 2 | G3: 400 | H3: =IF(LEN(G3)=0,"",VLOOKUP(G3,Issues!A:D,2,FALSE)) -> (400) Portales / Web-App | I3: =IF(LEN(G3)=0,"",VLOOKUP(G3,Issues!A:D,3,FALSE)) -> Portal evaluado con éxito. | J3: =IF(LEN(G3)=0,"",VLOOKUP(G3,Issues!A:D,4,FALSE)) -> Prueba OK | K3: =IF(LEN(G3)=0,"",IF(OR(J3="critico",J3="Medio",J3="Bajo"),"Issue",IF(J3="Prueba OK","OK",""))) -> OK
A4: 46109 | B4: =IF(LEN(A4)=0,"",TEXT(A4,"mmmm")) -> marzo | C4: =IF(LEN(A4)=0,"",TEXT(A4,"aaaa")) -> 2026 | D4: Web | E4: Opratel | F4: Opratel - Club 2 | G4: 400 | H4: =IF(LEN(G4)=0,"",VLOOKUP(G4,Issues!A:D,2,FALSE)) -> (400) Portales / Web-App | I4: =IF(LEN(G4)=0,"",VLOOKUP(G4,Issues!A:D,3,FALSE)) -> Portal evaluado con éxito. | J4: =IF(LEN(G4)=0,"",VLOOKUP(G4,Issues!A:D,4,FALSE)) -> Prueba OK | K4: =IF(LEN(G4)=0,"",IF(OR(J4="critico",J4="Medio",J4="Bajo"),"Issue",IF(J4="Prueba OK","OK",""))) -> OK
A5: 46038 | B5: =IF(LEN(A5)=0,"",TEXT(A5,"mmmm")) -> enero | C5: =IF(LEN(A5)=0,"",TEXT(A5,"aaaa")) -> 2026 | D5: Wap | E5: Celcom | F5: Celcom - Club 3 | G5: 100 | H5: =IF(LEN(G5)=0,"",VLOOKUP(G5,Issues!A:D,2,FALSE)) -> (100) Alta | I5: =IF(LEN(G5)=0,"",VLOOKUP(G5,Issues!A:D,3,FALSE)) -> Alta con éxito. | J5: =IF(LEN(G5)=0,"",VLOOKUP(G5,Issues!A:D,4,FALSE)) -> Prueba OK | K5: =IF(LEN(G5)=0,"",IF(OR(J5="critico",J5="Medio",J5="Bajo"),"Issue",IF(J5="Prueba OK","OK",""))) -> OK
A6: 46115 | B6: =IF(LEN(A6)=0,"",TEXT(A6,"mmmm")) -> abril | C6: =IF(LEN(A6)=0,"",TEXT(A6,"aaaa")) -> 2026 | D6: Web | E6: Chocolate | F6: Chocolate - Club 3 | G6: 113 | H6: =IF(LEN(G6)=0,"",VLOOKUP(G6,Issues!A:D,2,FALSE)) -> (100) Alta | I6: =IF(LEN(G6)=0,"",VLOOKUP(G6,Issues!A:D,3,FALSE)) -> Servicio suspendido. | J6: =IF(LEN(G6)=0,"",VLOOKUP(G6,Issues!A:D,4,FALSE)) -> Medio | K6: =IF(LEN(G6)=0,"",IF(OR(J6="critico",J6="Medio",J6="Bajo"),"Issue",IF(J6="Prueba OK","OK",""))) -> Issue
A7: 46153 | B7: =IF(LEN(A7)=0,"",TEXT(A7,"mmmm")) -> mayo | C7: =IF(LEN(A7)=0,"",TEXT(A7,"aaaa")) -> 2026 | D7: Wap | E7: T-Mobs | F7: T-Mobs - Club 1 | G7: 408 | H7: =IF(LEN(G7)=0,"",VLOOKUP(G7,Issues!A:D,2,FALSE)) -> (400) Portales / Web-App | I7: =IF(LEN(G7)=0,"",VLOOKUP(G7,Issues!A:D,3,FALSE)) -> Inconsistencias en los t&c del portal / web-app. | J7: =IF(LEN(G7)=0,"",VLOOKUP(G7,Issues!A:D,4,FALSE)) -> Critico | K7: =IF(LEN(G7)=0,"",IF(OR(J7="critico",J7="Medio",J7="Bajo"),"Issue",IF(J7="Prueba OK","OK",""))) -> Issue
A8: 46101 | B8: =IF(LEN(A8)=0,"",TEXT(A8,"mmmm")) -> marzo | C8: =IF(LEN(A8)=0,"",TEXT(A8,"aaaa")) -> 2026 | D8: Wap | E8: T-Mobs | F8: T-Mobs - Club 2 | G8: 104 | H8: =IF(LEN(G8)=0,"",VLOOKUP(G8,Issues!A:D,2,FALSE)) -> (100) Alta | I8: =IF(LEN(G8)=0,"",VLOOKUP(G8,Issues!A:D,3,FALSE)) -> No llega pin code. | J8: =IF(LEN(G8)=0,"",VLOOKUP(G8,Issues!A:D,4,FALSE)) -> Medio | K8: =IF(LEN(G8)=0,"",IF(OR(J8="critico",J8="Medio",J8="Bajo"),"Issue",IF(J8="Prueba OK","OK",""))) -> Issue
A9: 46110 | B9: =IF(LEN(A9)=0,"",TEXT(A9,"mmmm")) -> marzo | C9: =IF(LEN(A9)=0,"",TEXT(A9,"aaaa")) -> 2026 | D9: Otro | E9: airG | F9: airG - Club 2 | G9: 200 | H9: =IF(LEN(G9)=0,"",VLOOKUP(G9,Issues!A:D,2,FALSE)) -> (200) Contenidos | I9: =IF(LEN(G9)=0,"",VLOOKUP(G9,Issues!A:D,3,FALSE)) -> Contenidos recibido con éxito. | J9: =IF(LEN(G9)=0,"",VLOOKUP(G9,Issues!A:D,4,FALSE)) -> Prueba OK | K9: =IF(LEN(G9)=0,"",IF(OR(J9="critico",J9="Medio",J9="Bajo"),"Issue",IF(J9="Prueba OK","OK",""))) -> OK
A10: 46055 | B10: =IF(LEN(A10)=0,"",TEXT(A10,"mmmm")) -> febrero | C10: =IF(LEN(A10)=0,"",TEXT(A10,"aaaa")) -> 2026 | D10: Web | E10: Digevo | F10: Digevo - Club 2 | G10: 100 | H10: =IF(LEN(G10)=0,"",VLOOKUP(G10,Issues!A:D,2,FALSE)) -> (100) Alta | I10: =IF(LEN(G10)=0,"",VLOOKUP(G10,Issues!A:D,3,FALSE)) -> Alta con éxito. | J10: =IF(LEN(G10)=0,"",VLOOKUP(G10,Issues!A:D,4,FALSE)) -> Prueba OK | K10: =IF(LEN(G10)=0,"",IF(OR(J10="critico",J10="Medio",J10="Bajo"),"Issue",IF(J10="Prueba OK","OK",""))) -> OK
A11: 46120 | B11: =IF(LEN(A11)=0,"",TEXT(A11,"mmmm")) -> abril | C11: =IF(LEN(A11)=0,"",TEXT(A11,"aaaa")) -> 2026 | D11: Wap | E11: Chocolate | F11: Chocolate - Club 1 | G11: 113 | H11: =IF(LEN(G11)=0,"",VLOOKUP(G11,Issues!A:D,2,FALSE)) -> (100) Alta | I11: =IF(LEN(G11)=0,"",VLOOKUP(G11,Issues!A:D,3,FALSE)) -> Servicio suspendido. | J11: =IF(LEN(G11)=0,"",VLOOKUP(G11,Issues!A:D,4,FALSE)) -> Medio | K11: =IF(LEN(G11)=0,"",IF(OR(J11="critico",J11="Medio",J11="Bajo"),"Issue",IF(J11="Prueba OK","OK",""))) -> Issue
A12: 46082 | B12: =IF(LEN(A12)=0,"",TEXT(A12,"mmmm")) -> marzo | C12: =IF(LEN(A12)=0,"",TEXT(A12,"aaaa")) -> 2026 | D12: Otro | E12: KMD | F12: KMD - Club 2 | G12: 101 | H12: =IF(LEN(G12)=0,"",VLOOKUP(G12,Issues!A:D,2,FALSE)) -> (100) Alta | I12: =IF(LEN(G12)=0,"",VLOOKUP(G12,Issues!A:D,3,FALSE)) -> No se genero el alta - no hay respuesta al kw. | J12: =IF(LEN(G12)=0,"",VLOOKUP(G12,Issues!A:D,4,FALSE)) -> Critico | K12: =IF(LEN(G12)=0,"",IF(OR(J12="critico",J12="Medio",J12="Bajo"),"Issue",IF(J12="Prueba OK","OK",""))) -> Issue
A13: 46144 | B13: =IF(LEN(A13)=0,"",TEXT(A13,"mmmm")) -> mayo | C13: =IF(LEN(A13)=0,"",TEXT(A13,"aaaa")) -> 2026 | D13: Web | E13: Cykadas | F13: Cykadas - Club 2 | G13: 500 | H13: =IF(LEN(G13)=0,"",VLOOKUP(G13,Issues!A:D,2,FALSE)) -> (500) Baja / Cancelacion | I13: =IF(LEN(G13)=0,"",VLOOKUP(G13,Issues!A:D,3,FALSE)) -> Baja con éxito. | J13: =IF(LEN(G13)=0,"",VLOOKUP(G13,Issues!A:D,4,FALSE)) -> Prueba OK | K13: =IF(LEN(G13)=0,"",IF(OR(J13="critico",J13="Medio",J13="Bajo"),"Issue",IF(J13="Prueba OK","OK",""))) -> OK
... A202: 46100 | B202: =IF(LEN(A202)=0,"",TEXT(A202,"mmmm")) -> marzo | C202: =IF(LEN(A202)=0,"",TEXT(A202,"aaaa")) -> 2026 | D202: Web | E202: True Caller | F202: True Caller - Club 1 | G202: 703 | H202: =IF(LEN(G202)=0,"",VLOOKUP(G202,Issues!A:D,2,FALSE)) -> (700) Interaccion MO/MT (On Demand) | I202: =IF(LEN(G202)=0,"",VLOOKUP(G202,Issues!A:D,3,FALSE)) -> Fallas en la interaccion mo/mt. | J202: =IF(LEN(G202)=0,"",VLOOKUP(G202,Issues!A:D,4,FALSE)) -> Critico | K202: =IF(LEN(G202)=0,"",IF(OR(J202="critico",J202="Medio",J202="Bajo"),"Issue",IF(J202="Prueba OK","OK",""))) -> Issue
A203: 46079 | B203: =IF(LEN(A203)=0,"",TEXT(A203,"mmmm")) -> febrero | C203: =IF(LEN(A203)=0,"",TEXT(A203,"aaaa")) -> 2026 | D203: Web | E203: Celcom | F203: Celcom - Club 2 | G203: 500 | H203: =IF(LEN(G203)=0,"",VLOOKUP(G203,Issues!A:D,2,FALSE)) -> (500) Baja / Cancelacion | I203: Flujo MO/MT con éxito. | J203: Prueba OK | K203: =IF(LEN(G203)=0,"",IF(OR(J203="critico",J203="Medio",J203="Bajo"),"Issue",IF(J203="Prueba OK","OK",""))) -> OK
A204: 46146 | B204: =IF(LEN(A204)=0,"",TEXT(A204,"mmmm")) -> mayo | C204: =IF(LEN(A204)=0,"",TEXT(A204,"aaaa")) -> 2026 | D204: Wap | E204: GPM | F204: GPM - Club 2 | G204: 403 | H204: =IF(LEN(G204)=0,"",VLOOKUP(G204,Issues!A:D,2,FALSE)) -> (400) Portales / Web-App | I204: Alta con éxito. | J204: Prueba OK | K204: =IF(LEN(G204)=0,"",IF(OR(J204="critico",J204="Medio",J204="Bajo"),"Issue",IF(J204="Prueba OK","OK",""))) -> OK
A205: 46082 | B205: =IF(LEN(A205)=0,"",TEXT(A205,"mmmm")) -> marzo | C205: =IF(LEN(A205)=0,"",TEXT(A205,"aaaa")) -> 2026 | D205: Tienda | E205: FaroMobile | F205: FaroMobile - Club 3 | G205: 300 | H205: =IF(LEN(G205)=0,"",VLOOKUP(G205,Issues!A:D,2,FALSE)) -> (300) Cobros | I205: Inconsistencias con el cobro escalonado. | J205: Critico | K205: =IF(LEN(G205)=0,"",IF(OR(J205="critico",J205="Medio",J205="Bajo"),"Issue",IF(J205="Prueba OK","OK",""))) -> Issue
A206: 46145 | B206: =IF(LEN(A206)=0,"",TEXT(A206,"mmmm")) -> mayo | C206: =IF(LEN(A206)=0,"",TEXT(A206,"aaaa")) -> 2026 | D206: Web | E206: FaroMobile | F206: FaroMobile - Club 1 | G206: 700 | H206: =IF(LEN(G206)=0,"",VLOOKUP(G206,Issues!A:D,2,FALSE)) -> (700) Interaccion MO/MT (On Demand) | I206: Entrega de mensajeria sms con delay. | J206: Bajo | K206: =IF(LEN(G206)=0,"",IF(OR(J206="critico",J206="Medio",J206="Bajo"),"Issue",IF(J206="Prueba OK","OK",""))) -> Issue
A207: 46126 | B207: =IF(LEN(A207)=0,"",TEXT(A207,"mmmm")) -> abril | C207: =IF(LEN(A207)=0,"",TEXT(A207,"aaaa")) -> 2026 | D207: Web | E207: Cykadas | F207: Cykadas - Club 1 | G207: 700 | H207: =IF(LEN(G207)=0,"",VLOOKUP(G207,Issues!A:D,2,FALSE)) -> (700) Interaccion MO/MT (On Demand) | I207: Error/inconsistencia en t&c en sms. | J207: Critico | K207: =IF(LEN(G207)=0,"",IF(OR(J207="critico",J207="Medio",J207="Bajo"),"Issue",IF(J207="Prueba OK","OK",""))) -> Issue
A208: 46079 | B208: =IF(LEN(A208)=0,"",TEXT(A208,"mmmm")) -> febrero | C208: =IF(LEN(A208)=0,"",TEXT(A208,"aaaa")) -> 2026 | D208: Web | E208: Digital Virgo | F208: Digital Virgo - Club 1 | G208: 100 | H208: =IF(LEN(G208)=0,"",VLOOKUP(G208,Issues!A:D,2,FALSE)) -> (100) Alta | I208: Cobro en valor y forma correcto. | J208: Prueba OK | K208: =IF(LEN(G208)=0,"",IF(OR(J208="critico",J208="Medio",J208="Bajo"),"Issue",IF(J208="Prueba OK","OK",""))) -> OK
A209: 46079 | B209: =IF(LEN(A209)=0,"",TEXT(A209,"mmmm")) -> febrero | C209: =IF(LEN(A209)=0,"",TEXT(A209,"aaaa")) -> 2026 | D209: Wap | E209: Digevo | F209: Digevo - Club 1 | G209: 301 | H209: =IF(LEN(G209)=0,"",VLOOKUP(G209,Issues!A:D,2,FALSE)) -> (300) Cobros | I209: No entrega confirmacion de cobro. | J209: Critico | K209: =IF(LEN(G209)=0,"",IF(OR(J209="critico",J209="Medio",J209="Bajo"),"Issue",IF(J209="Prueba OK","OK",""))) -> Issue
A210: 46111 | B210: =IF(LEN(A210)=0,"",TEXT(A210,"mmmm")) -> marzo | C210: =IF(LEN(A210)=0,"",TEXT(A210,"aaaa")) -> 2026 | D210: Otro | E210: FaroMobile | F210: FaroMobile - Club 3 | G210: 300 | H210: =IF(LEN(G210)=0,"",VLOOKUP(G210,Issues!A:D,2,FALSE)) -> (300) Cobros | I210: =IF(LEN(G210)=0,"",VLOOKUP(G210,Issues!A:D,3,FALSE)) -> Cobro en valor y forma correcto. | J210: =IF(LEN(G210)=0,"",VLOOKUP(G210,Issues!A:D,4,FALSE)) -> Prueba OK | K210: =IF(LEN(G210)=0,"",IF(OR(J210="critico",J210="Medio",J210="Bajo"),"Issue",IF(J210="Prueba OK","OK",""))) -> OK
A211: 46112 | B211: =IF(LEN(A211)=0,"",TEXT(A211,"mmmm")) -> marzo | C211: =IF(LEN(A211)=0,"",TEXT(A211,"aaaa")) -> 2026 | D211: Web | E211: Celcom | F211: Celcom - Club 1 | G211: 301 | H211: =IF(LEN(G211)=0,"",VLOOKUP(G211,Issues!A:D,2,FALSE)) -> (300) Cobros | I211: =IF(LEN(G211)=0,"",VLOOKUP(G211,Issues!A:D,3,FALSE)) -> No llego contenido (si hubo cobro). | J211: =IF(LEN(G211)=0,"",VLOOKUP(G211,Issues!A:D,4,FALSE)) -> Critico | K211: =IF(LEN(G211)=0,"",IF(OR(J211="critico",J211="Medio",J211="Bajo"),"Issue",IF(J211="Prueba OK","OK",""))) -> Issue
A212: 46098 | B212: =IF(LEN(A212)=0,"",TEXT(A212,"mmmm")) -> marzo | C212: =IF(LEN(A212)=0,"",TEXT(A212,"aaaa")) -> 2026 | D212: Web | E212: Cykadas | F212: Cykadas - Club 3 | G212: 301 | H212: =IF(LEN(G212)=0,"",VLOOKUP(G212,Issues!A:D,2,FALSE)) -> (300) Cobros | I212: =IF(LEN(G212)=0,"",VLOOKUP(G212,Issues!A:D,3,FALSE)) -> No llego contenido (si hubo cobro). | J212: =IF(LEN(G212)=0,"",VLOOKUP(G212,Issues!A:D,4,FALSE)) -> Critico | K212: =IF(LEN(G212)=0,"",IF(OR(J212="critico",J212="Medio",J212="Bajo"),"Issue",IF(J212="Prueba OK","OK",""))) -> Issue
A213: 46112 | B213: =IF(LEN(A213)=0,"",TEXT(A213,"mmmm")) -> marzo | C213: =IF(LEN(A213)=0,"",TEXT(A213,"aaaa")) -> 2026 | D213: Tienda | E213: Renxo | F213: Renxo - Club 1 | G213: 306 | H213: =IF(LEN(G213)=0,"",VLOOKUP(G213,Issues!A:D,2,FALSE)) -> (300) Cobros | I213: =IF(LEN(G213)=0,"",VLOOKUP(G213,Issues!A:D,3,FALSE)) -> Inconsistencias en la recurrencia del cobro. | J213: =IF(LEN(G213)=0,"",VLOOKUP(G213,Issues!A:D,4,FALSE)) -> Critico | K213: =IF(LEN(G213)=0,"",IF(OR(J213="critico",J213="Medio",J213="Bajo"),"Issue",IF(J213="Prueba OK","OK",""))) -> Issue
A214: 46055 | B214: =IF(LEN(A214)=0,"",TEXT(A214,"mmmm")) -> febrero | C214: =IF(LEN(A214)=0,"",TEXT(A214,"aaaa")) -> 2026 | D214: Web | E214: T-Mobs | F214: T-Mobs - Club 1 | G214: 700 | H214: =IF(LEN(G214)=0,"",VLOOKUP(G214,Issues!A:D,2,FALSE)) -> (700) Interaccion MO/MT (On Demand) | I214: =IF(LEN(G214)=0,"",VLOOKUP(G214,Issues!A:D,3,FALSE)) -> Flujo MO/MT con éxito. | J214: =IF(LEN(G214)=0,"",VLOOKUP(G214,Issues!A:D,4,FALSE)) -> Prueba OK | K214: =IF(LEN(G214)=0,"",IF(OR(J214="critico",J214="Medio",J214="Bajo"),"Issue",IF(J214="Prueba OK","OK",""))) -> OK
A215: 46148 | B215: =IF(LEN(A215)=0,"",TEXT(A215,"mmmm")) -> mayo | C215: =IF(LEN(A215)=0,"",TEXT(A215,"aaaa")) -> 2026 | D215: Web | E215: Celcom | F215: Celcom - Club 1 | G215: 200 | H215: =IF(LEN(G215)=0,"",VLOOKUP(G215,Issues!A:D,2,FALSE)) -> (200) Contenidos | I215: =IF(LEN(G215)=0,"",VLOOKUP(G215,Issues!A:D,3,FALSE)) -> Contenidos recibido con éxito. | J215: =IF(LEN(G215)=0,"",VLOOKUP(G215,Issues!A:D,4,FALSE)) -> Prueba OK | K215: =IF(LEN(G215)=0,"",IF(OR(J215="critico",J215="Medio",J215="Bajo"),"Issue",IF(J215="Prueba OK","OK",""))) -> OK
A216: 46140 | B216: =IF(LEN(A216)=0,"",TEXT(A216,"mmmm")) -> abril | C216: =IF(LEN(A216)=0,"",TEXT(A216,"aaaa")) -> 2026 | D216: Wap | E216: KMD | F216: KMD - Club 2 | G216: 801 | H216: =IF(LEN(G216)=0,"",VLOOKUP(G216,Issues!A:D,2,FALSE)) -> (800) Politicas especiales operadores | I216: =IF(LEN(G216)=0,"",VLOOKUP(G216,Issues!A:D,3,FALSE)) -> No da respuesta a kw regulatorio. | J216: =IF(LEN(G216)=0,"",VLOOKUP(G216,Issues!A:D,4,FALSE)) -> Critico | K216: =IF(LEN(G216)=0,"",IF(OR(J216="critico",J216="Medio",J216="Bajo"),"Issue",IF(J216="Prueba OK","OK",""))) -> Issue
A217: 46099 | B217: =IF(LEN(A217)=0,"",TEXT(A217,"mmmm")) -> marzo | C217: =IF(LEN(A217)=0,"",TEXT(A217,"aaaa")) -> 2026 | D217: Web | E217: Bennu | F217: Bennu - Club 2 | G217: 112 | H217: =IF(LEN(G217)=0,"",VLOOKUP(G217,Issues!A:D,2,FALSE)) -> (100) Alta | I217: =IF(LEN(G217)=0,"",VLOOKUP(G217,Issues!A:D,3,FALSE)) -> Falla en alta a traves de tienda. | J217: =IF(LEN(G217)=0,"",VLOOKUP(G217,Issues!A:D,4,FALSE)) -> Critico | K217: =IF(LEN(G217)=0,"",IF(OR(J217="critico",J217="Medio",J217="Bajo"),"Issue",IF(J217="Prueba OK","OK",""))) -> Issue
A218: 46052 | B218: =IF(LEN(A218)=0,"",TEXT(A218,"mmmm")) -> enero | C218: =IF(LEN(A218)=0,"",TEXT(A218,"aaaa")) -> 2026 | D218: Wap | E218: GPM | F218: GPM - Club 2 | G218: 200 | H218: =IF(LEN(G218)=0,"",VLOOKUP(G218,Issues!A:D,2,FALSE)) -> (200) Contenidos | I218: =IF(LEN(G218)=0,"",VLOOKUP(G218,Issues!A:D,3,FALSE)) -> Contenidos recibido con éxito. | J218: =IF(LEN(G218)=0,"",VLOOKUP(G218,Issues!A:D,4,FALSE)) -> Prueba OK | K218: =IF(LEN(G218)=0,"",IF(OR(J218="critico",J218="Medio",J218="Bajo"),"Issue",IF(J218="Prueba OK","OK",""))) -> OK
A219: 46129 | B219: =IF(LEN(A219)=0,"",TEXT(A219,"mmmm")) -> abril | C219: =IF(LEN(A219)=0,"",TEXT(A219,"aaaa")) -> 2026 | D219: Web | E219: Opratel | F219: Opratel - Club 2 | G219: 507 | H219: =IF(LEN(G219)=0,"",VLOOKUP(G219,Issues!A:D,2,FALSE)) -> (500) Baja / Cancelacion | I219: =IF(LEN(G219)=0,"",VLOOKUP(G219,Issues!A:D,3,FALSE)) -> No funciona la baja desde portal / web app. | J219: =IF(LEN(G219)=0,"",VLOOKUP(G219,Issues!A:D,4,FALSE)) -> Critico | K219: =IF(LEN(G219)=0,"",IF(OR(J219="critico",J219="Medio",J219="Bajo"),"Issue",IF(J219="Prueba OK","OK",""))) -> Issue
A220: 46054 | B220: =IF(LEN(A220)=0,"",TEXT(A220,"mmmm")) -> febrero | C220: =IF(LEN(A220)=0,"",TEXT(A220,"aaaa")) -> 2026 | D220: Otro | E220: airG | F220: airG - Club 2 | G220: 407 | H220: =IF(LEN(G220)=0,"",VLOOKUP(G220,Issues!A:D,2,FALSE)) -> (400) Portales / Web-App | I220: =IF(LEN(G220)=0,"",VLOOKUP(G220,Issues!A:D,3,FALSE)) -> No funciona la interaccion. | J220: =IF(LEN(G220)=0,"",VLOOKUP(G220,Issues!A:D,4,FALSE)) -> Critico | K220: =IF(LEN(G220)=0,"",IF(OR(J220="critico",J220="Medio",J220="Bajo"),"Issue",IF(J220="Prueba OK","OK",""))) -> Issue
A221: 46045 | B221: =IF(LEN(A221)=0,"",TEXT(A221,"mmmm")) -> enero | C221: =IF(LEN(A221)=0,"",TEXT(A221,"aaaa")) -> 2026 | D221: Web | E221: Digevo | F221: Digevo - Club 1 | G221: 800 | H221: =IF(LEN(G221)=0,"",VLOOKUP(G221,Issues!A:D,2,FALSE)) -> (800) Politicas especiales operadores | I221: =IF(LEN(G221)=0,"",VLOOKUP(G221,Issues!A:D,3,FALSE)) -> Politicas de los operadores cumplidas. | J221: =IF(LEN(G221)=0,"",VLOOKUP(G221,Issues!A:D,4,FALSE)) -> Prueba OK | K221: =IF(LEN(G221)=0,"",IF(OR(J221="critico",J221="Medio",J221="Bajo"),"Issue",IF(J221="Prueba OK","OK",""))) -> OK
... A1001: 46157 | B1001: =IF(LEN(A1001)=0,"",TEXT(A1001,"mmmm")) -> mayo | C1001: =IF(LEN(A1001)=0,"",TEXT(A1001,"aaaa")) -> 2026 | D1001: Wap | E1001: FaroMobile | F1001: FaroMobile - Club 1 | G1001: 500 | H1001: =IF(LEN(G1001)=0,"",VLOOKUP(G1001,Issues!A:D,2,FALSE)) -> (500) Baja / Cancelacion | I1001: =IF(LEN(G1001)=0,"",VLOOKUP(G1001,Issues!A:D,3,FALSE)) -> Baja con éxito. | J1001: =IF(LEN(G1001)=0,"",VLOOKUP(G1001,Issues!A:D,4,FALSE)) -> Prueba OK | K1001: =IF(LEN(G1001)=0,"",IF(OR(J1001="critico",J1001="Medio",J1001="Bajo"),"Issue",IF(J1001="Prueba OK","OK",""))) -> OK

Sheet tablas dinamicas
B1: Mes | C1: febrero | E1: Pruebas Exitosas Vs Issues
C3: Cuenta de Resultado
B4: OK | C4: 90
B5: Issue | C5: 113
B6: Total general | C6: 203
B24: Mes | C24: febrero
B26: Cuenta de Resultado
C27: OK | D27: Issue | E27: Total general
B28: (100) Alta | C28: 15 | D28: 32 | E28: 47
B29: (200) Contenidos | C29: 8 | D29: 23 | E29: 31
B30: (300) Cobros | C30: 15 | D30: 13 | E30: 28
B31: (400) Portales / Web-App | C31: 9 | D31: 26 | E31: 35
B32: (500) Baja / Cancelacion | C32: 16 | D32: 9 | E32: 25
B33: (700) Interaccion MO/MT (On Demand) | C33: 13 | D33: 6 | E33: 19
B34: (800) Politicas especiales operadores | C34: 14 | D34: 4 | E34: 18
B35: Total general | C35: 90 | D35: 113 | E35: 203
B38: Mes | C38: febrero
B39: Resultado | C39: Issue
C41: Cuenta de Resultado
B42: 409 no cumple con caracteristicas de diseño responsive. | C42: 2
B43: Cobro doble vez. | C43: 1
B44: Cobro valor diferente al autorizado. | C44: 2
B45: Contenido desactualizado. | C45: 4
B46: Contenido no apropiado - fuera de las politicas del operador. | C46: 3
B47: Contenido repetido. | C47: 3
B48: Entrega de mensaje fuera de horario establecido. | C48: 1
B49: Entrega de mensajeria sms con delay. | C49: 4
B50: Error/inconsistencia en t&c en sms. | C50: 3
B51: Falla en alta a traves de ivr. | C51: 2
B52: Falla en alta a traves de sim. | C52: 3
B53: Falla en alta a traves de tienda. | C53: 3
... B93: Total general | C93: 113
B97: Mes | C97: enero
B98: Proveedor | C98: airG
B100: Cuenta de Resultado
C101: OK | D101: Issue | E101: Total general
B102: (100) Alta | D102: 3 | E102: 3
B103: (200) Contenidos | C103: 1 | D103: 1 | E103: 2
B104: (300) Cobros | C104: 1 | E104: 1
B105: (400) Portales / Web-App | D105: 2 | E105: 2
...

Sheet Issues
A1: Codigo de Falla | B1: Categoria | C1: Descripcion | D1: Nivel
A2: 100 | B2: (100) Alta | C2: Alta con éxito. | D2: Prueba OK
A3: 101 | B3: (100) Alta | C3: No se genero el alta - no hay respuesta al kw. | D3: Critico
A4: 102 | B4: (100) Alta | C4: Falla en doble optin en sms. | D4: Critico
A5: 103 | B5: (100) Alta | C5: Inconsistencia en el welcome. | D5: Critico
A6: 104 | B6: (100) Alta | C6: No llega pin code. | D6: Medio
A7: 105 | B7: (100) Alta | C7: Inconsistencia en el pin code. | D7: Medio
A8: 106 | B8: (100) Alta | C8: Falla en lp de suscripción web. | D8: Critico
A9: 107 | B9: (100) Alta | C9: Falla en lp de suscripción wap - header enrichment. | D9: Critico
A10: 108 | B10: (100) Alta | C10: Inconsistencias en t&c en la lp. | D10: Critico
A11: 109 | B11: (100) Alta | C11: Fallas en estructura o diseño de la lp. | D11: Medio
A12: 110 | B12: (100) Alta | C12: Falla en alta a traves de ivr. | D12: Critico
A13: 111 | B13: (100) Alta | C13: Falla en alta a traves de sim. | D13: Critico
... A64: 802 | B64: (800) Politicas especiales operadores | C64: Falla en colilla legal con info del cp. | D64: Critico

Sheet clubs
A1: Opratel | B1: Opratel - Club 1
A2: Opratel | B2: Opratel - Club 2
A3: Opratel | B3: Opratel - Club 3
A4: Chocolate | B4: Chocolate - Club 1
A5: Chocolate | B5: Chocolate - Club 2
A6: Chocolate | B6: Chocolate - Club 3
A7: Renxo | B7: Renxo - Club 1
A8: Renxo | B8: Renxo - Club 2
A9: Renxo | B9: Renxo - Club 3
A10: Digital Virgo | B10: Digital Virgo - Club 1
A11: Digital Virgo | B11: Digital Virgo - Club 2
A12: Digital Virgo | B12: Digital Virgo - Club 3
... A54: Digevo | B54: Digevo - Club 3

Sheet CPs
A1: Opratel
A2: Chocolate
A3: Renxo
A4: Digital Virgo
A5: Bennu
A6: T-Mobs
A7: airG
A8: Zed
A9: GPM
A10: Celcom
A11: AWG
A12: Cykadas
... A18: Digevo

Sheet Canal
A1: SMS
A2: SAT
A3: Web
A4: Wap
A5: Sim
A6: Tienda
A7: Otro

Sheet Fecha
A1: 46023
A2: 46024
A3: 46025
A4: 46026
A5: 46027
A6: 46028
A7: 46029
A8: 46030
A9: 46031
A10: 46032
A11: 46033
A12: 46034
... A365: 46387
